"""Utilities for compatibility with older versions of Python
"""

import sys

import asyncio

if sys.version_info >= (3, 11):
    from wsgiref.types import StartResponse
    from wsgiref.types import WSGIEnvironment
else:
    from typing import Callable as StartResponse
    WSGIEnvironment = dict


def asyncio_run(awaitable):
    """asyncio.run for Python 3.6"""
    try:
        aio_run = asyncio.run
    except AttributeError:
        # Python 3.6
        loop = asyncio.get_event_loop()
        return loop.run_until_complete(awaitable)
        # We should also call loop.close() here, but that would mean
        # the event loop can't be used in other code:
        # * when using freezeyt as a library, and
        # * in our own tests.
        # So, we cheat a bit and don't call close().
        # (Python 3.6 support is ending soon, anyway.)
    else:
        return aio_run(awaitable)


def asyncio_create_task(coroutine, name):
    """asyncio.create_task for Python 3.6 & 3.7"""
    if sys.version_info < (3, 7):
        # Python 3.6
        return asyncio.ensure_future(coroutine)
    elif sys.version_info < (3, 8):
        # Python 3.7
        return asyncio.create_task(coroutine)
    else:
        return asyncio.create_task(coroutine, name=name)


def get_running_loop():
    try:
        get_loop = asyncio.get_running_loop
    except AttributeError:
        # Python 3.6
        return asyncio.get_event_loop()
    else:
        return get_loop()


# In Python 3.11, freezeyt's MultiError derives from ExceptionGroup
# and can be used with the `except*` statement.
# In older versions, it derives from Exception instead.
if sys.version_info >= (3, 11):
    _MultiErrorBase = ExceptionGroup
    HAVE_EXCEPTION_GROUP = True
else:
    _MultiErrorBase = Exception
    HAVE_EXCEPTION_GROUP = False
